# 1. panic

错误最简单的错误处理机制就是 panic，它会打印一个错误消息，然后回退(unwind)任务，且通常退出程序

```rust
fn give_princess(gift: &str) {
    if gift == "snake" {
        panic!("AAAAAaaaaa!!!");
    }

    println!("I love {}s!!!", gift);
}

fn main() {
    give_princess("teddy bear");
    give_princess("snake");
    give_princess("babbie");
}
```



# 2. Option

枚举类型 `Option<T>`:

- `Some(T)`：找到一个属于 T 类型的元素
- `None`：找不到相应元素

处理方式：

- match 显式处理
- unwrap 隐式处理，它要么返回 Some 内部的元素，要么就 panic



## 2.1 使用 `?` 解开 Option

`?` 简化 match 匹配的复杂性

```rust
struct Person {
    job: Option<Job>
}

#[derive(Copy, Clone)]
struct Job {
    phone_number: Option<PhoneNumber>
}

#[derive(Copy, Clone)]
struct PhoneNumber {
    area_code: Option<u8>,
    number: u32,
}

impl Person {
    fn work_phone_area_code(&self) -> Option<u8> {
        // 没有`?`运算符的话，将需要很多的嵌套的 `match` 语句
        self.job?.phone_number?.area_code
    }
}

fn main() {
    let p = Person {
        job: Some(Job{
            phone_number: Some(PhoneNumber{
                area_code: Some(25),
                number: 56712111,
            })
        })
    };

    assert_eq!(p.work_phone_area_code(), Some(25));
}
```



## 2.2 组合算子：map

Option 提供内置方法 map()，多个不同的 map() 可以串起来，使得操作更加灵活

```rust
#![allow(dead_code)]

#[derive(Debug)] enum Food { Apple, Carrot, Potato }

#[derive(Debug)] struct Peeled(Food);
#[derive(Debug)] struct Chopped(Food);
#[derive(Debug)] struct Cooked(Food);

fn peel(food: Option<Food>) -> Option<Peeled> {
    match food {
        Some(food) => Some(Peeled(food)),
        None => None,
    }
}

fn chop(peeled: Option<Peeled>) -> Option<Chopped> {
    match peeled {
        Some(Peeled(food)) => Some(Chopped(food)),
        None => None,
    }
}

fn cook(chopped: Option<Chopped>) -> Option<Cooked> {
    // map 代替 match 处理各种情况
    chopped.map(|Chopped(food)| Cooked(food))
}

fn process(food: Option<Food>) -> Option<Cooked> {
    // 链式处理
    food.map(|f| Peeled(f))
        .map(|Peeled(f)| Chopped(f))
        .map(|Chopped(f)| Cooked(f))
}

fn eat(food: Option<Cooked>) {
    match food {
        Some(food) => println!("Mmm, I love {:?}", food),
        None => println!("Oh no! It wasn't edible."),
    }
}

fn main() {
    let apple = Some(Food::Apple);
    let carrot = Some(Food::Carrot);
    let potato = None;

    let cooked_apple = cook(chop(peel(apple)));
    let cooked_carrot = cook(chop(peel(carrot)));

    let cooked_potato = process(potato);

    eat(cooked_apple);
    eat(cooked_carrot);
    eat(cooked_potato);
}
```



## 2.3 组合算子：and_then

`map()` 以链式调用的方式简化了 match 语句。但如果以 `Option<T>` 的函数作为 `map()` 的参数，会导致出现嵌套形式 `Option<Option<T>>`，这种多层串联调用会变得混乱。为此引入 `and_then()`，某些语言也称为 flatmap，它使被 Option 包裹的值来调用其输入函数并返回解构，如果 Option 是 None，那么它返回 None。

```rust
#![allow(dead_code)]

#[derive(Debug)] enum Food { CordonBleu, Steak, Sushi }
#[derive(Debug)] enum Day { Monday, Tuesday, Wednesday }

fn have_ingredients(food: Food) -> Option<Food> {
    match food {
        Food::Sushi => None,
        _ => Some(food),
    }
}

fn have_recipe(food: Food) -> Option<Food> {
    match food {
        Food::CordonBleu => None,
        _ => Some(food),
    }
}

fn cookable_v1(food: Food) -> Option<Food> {
    match have_ingredients(food) {
        None => None,
        Some(food) => match have_recipe(food) {
            None => None,
            Some(food) => Some(food),
        },
    }
}

fn cookable_v2(food: Food) -> Option<Food> {
    have_ingredients(food).and_then(have_recipe)
}

fn eat(food: Food, day: Day) {
    match cookable_v2(food) {
        Some(food) => println!("Yay! On {:?} we get to eat {:?}.", day, food),
        None => println!("Oh no. We don't get to eat on {:?}?", day),
    }
}

fn main() {
    let (cordon_bleu, steak, sushi) = (Food::CordonBleu, Food::Steak, Food::Sushi);

    eat(cordon_bleu, Day::Monday);
    eat(steak, Day::Tuesday);
    eat(sushi, Day::Wednesday);
}
```



# 3. Result

Result 是 Option 类型的扩展，它可以有两个结果的其中一个：

- `Ok<T>`：找到 T 元素
- `Err<E>`：找到 E 元素，E 即错误类型



## 3.1 组合算子

Option 的 map, and_then 等组合算子也为 Result 实现了

```rust
#![allow(dead_code)]
use std::num::ParseIntError;

fn multiply_v1(s1: &str, s2: &str) -> Result<i32, ParseIntError> {
    match s1.parse::<i32>() {
        Ok(n1) => {
            match s2.parse::<i32>() {
                Ok(n2) => {
                    Ok(n1 * n2)
                },
                Err(e) => Err(e),
            }
        },
        Err(e) => Err(e),
    }
}

fn multiply_v2(s1: &str, s2: &str) -> Result<i32, ParseIntError> {
    s1.parse::<i32>().and_then(|n1| {
        s2.parse::<i32>().map(|n2| n1 * n2)
    })
}

fn print(result: Result<i32, ParseIntError>) {
    match result {
        Ok(n) => println!("n is {}", n),
        Err(e) => println!("Error: {}", e),
    }
}

fn main() {
    let r1 = multiply_v2("32", "5");
    print(r1);

    let r2 = multiply_v2("12", "hk");
    print(r2);
}
```



## 3.2 别名

```rust
use std::num::ParseIntError;

type AliasedResult<T> = Result<T, ParseIntError>;

fn multiply(s1: &str, s2: &str) -> AliasedResult<i32> {
    s1.parse::<i32>().and_then(|n1| {
        s2.parse::<i32>().map(|n2| n1 * n2)
    })
}

fn print(result: AliasedResult<i32>) {
    match result {
        Ok(n) => println!("n is {}", n),
        Err(e) => println!("Error: {}", e),
    }
}

fn main() {
    let r1 = multiply("5", "7");
    print(r1);

    let r2 = multiply("t", "2");
    print(r2);
}
```



## 3.3 提前返回

如果发生错误，则停止函数指向并返回错误，这样的代码更好写、更易读。

```rust
use std::num::ParseIntError;

fn multiply(s1: &str, s2: &str) -> Result<i32, ParseIntError> {
    let n1 = match s1.parse::<i32>() {
        Ok(n1) => n1,
        Err(e) => return Err(e),
    };

    let n2 = match s2.parse::<i32>() {
        Ok(n2) => n2,
        Err(e) => return Err(e),
    };

    Ok(n1 * n2)
}

fn print(result: Result<i32, ParseIntError>) {
    match result {
        Ok(n) => println!("n is {}", n),
        Err(e) => println!("Error: {}", e),
    }
}

fn main() {
    let r1 = multiply("3", "4");
    print(r1);

    let r2 = multiply("w", "8");
    print(r2);
}
```



## 3.4 引入 `?`

unwrap 可能导致 panic，需要层层嵌套判断。如果只想把里面的变量拿出来，可使用 `?`，它几乎就等于一个返回 Error 而不是 panic 的 unwrap

```rust
use std::num::ParseIntError;

fn multiply(s1: &str, s2: &str) -> Result<i32, ParseIntError> {
    let n1 = s1.parse::<i32>()?;
    let n2 = s2.parse::<i32>()?;

    Ok(n1 * n2)
}

fn print(result: Result<i32, ParseIntError>) {
    match result {
        Ok(n) => println!("n is {}", n),
        Err(e) => println!("Error: {}", e),
    }
}

fn main() {
    let r1 = multiply("3", "9");
    print(r1);

    let r2 = multiply("t", "3");
    print(r2);
}
```



## 3.5 `try!` 宏

`try!` 宏具有和 `?` 相同的功能，主要使用在老代码中

```rust
use std::num::ParseIntError;

fn multiply(s1: &str, s2: &str) -> Result<i32, ParseIntError> {
    // `try!()` macro is deprecated
    let n1 = r#try!(s1.parse::<i32>());
    let n2 = r#try!(s2.parse::<i32>());

    Ok(n1 * n2)
}

fn print(result: Result<i32, ParseIntError>) {
    match result {
        Ok(n) => println!("n is {}", n),
        Err(e) => println!("Error: {}", e),
    }
}

fn main() {
    print(multiply("5", "8"));
    print(multiply("s", "4"));
}
```



# 4. 处理多种错误

## 4.1 从 Option 中取出 Result

处理混合错误类型的最基本手段就是让它们相互包容

```rust
use std::num::ParseIntError;

// 通过 Option 包装 Result
fn double_first_v1(vec: Vec<&str>) -> Option<Result<i32, ParseIntError>> {
    vec.first().map(|first| {
        first.parse::<i32>().map(|n| n * 2)
    })
}

// Option 和 Result 互换
fn double_first(vec: Vec<&str>) -> Result<Option<i32>, ParseIntError> {
    let opt = vec.first().map(|first| {
       first.parse::<i32>().map(|n| n * 2)
    });

    opt.map_or(Ok(None), |r| r.map(Some))
}

fn main() {
    let numbers = vec!["21", "42", "16"];
    let empty = vec![];
    let strings = vec!["do", "13", "20"];

    println!("The first double is {:?}", double_first(numbers));
    println!("The first double is {:?}", double_first(empty));
    println!("The first double is {:?}", double_first(strings));
}
```



## 4.2 定义一个错误类型

自定义错误类型：

- 用同一个类型代表多种错误
- 向用户提供清楚的错误信息
- 能够容易地与其他类型比较
  - 好的例子：Err(EmptyVec)
  - 坏的例子：Err("Please use a vector with at least one element".to_owned())
- 能够容纳错误的具体信息
  - 好的例子：Err(BadChar(c, position))
  - 坏的例子：Err("+ cannot be used here".to_owned())
- 能够与其他错误很好地整合

```rust
use std::error;
use std::fmt;

type Result<T> = std::result::Result<T, DoubleError>;

#[derive(Debug, Clone)]
struct DoubleError;

impl fmt::Display for DoubleError {
    fn fmt(&self, f: &mut fmt::Formatter<'_>) -> fmt::Result {
        write!(f, "invalid first item to double")
    }
}

impl error::Error for DoubleError {
    fn source(&self) -> Option<&(dyn error::Error + 'static)> {
        None
    }
}

fn double_first(vec: Vec<&str>) -> Result<i32> {
    vec.first()
        .ok_or(DoubleError)
        .and_then(|s| {
            s.parse::<i32>()
                .map_err(|_| DoubleError)
                .map(|n| n * 2)
        })
}

fn print(result: Result<i32>) {
    match result {
        Ok(n) => println!("The first double is {}", n),
        Err(e) => println!("Error: {}", e),
    }
}

fn main() {
    let numbers = vec!["21", "42", "16"];
    let empty = vec![];
    let strings = vec!["do", "13", "20"];

    print(double_first(numbers));
    print(double_first(empty));
    print(double_first(strings));
}
```



## 4.3 把错误装箱

如果想写简单的代码，又想保留原始错误信息，可将它们装箱 (Box)。但这样做的坏处是，被包装的错误类型，只能在运行时了解，而不能被静态地判别。

对任何实现了 Error trait 的类型，标准库 Box 通过 From 为其提供到 `Box<Error>` 的转换

```rust
use std::{error, fmt};

type Result<T> = std::result::Result<T, Box<dyn error::Error>>;

#[derive(Debug, Clone)]
struct EmptyVec;

impl fmt::Display for EmptyVec {
    fn fmt(&self, f: &mut fmt::Formatter<'_>) -> fmt::Result {
        write!(f, "invalid first item to double")
    }
}

impl error::Error for EmptyVec {
    fn description(&self) -> &str {
        "invalid first item to double"
    }

    fn cause(&self) -> Option<&dyn error::Error> {
        None
    }
}

fn double_first(vec: Vec<&str>) -> Result<i32> {
    vec.first()
        .ok_or_else(|| EmptyVec.into())  // 装箱
        .and_then(|s| {
            s.parse::<i32>()
                .map_err(|e| e.into()) // 装箱
                .map(|n| n * 2)
        })
}

fn print(result: Result<i32>) {
    match result {
        Ok(n) => println!("The first double is {}", n),
        Err(e) => println!("Error: {}", e),
    }
}

fn main() {
    let numbers = vec!["21", "42", "16"];
    let empty = vec![];
    let strings = vec!["do", "13", "20"];

    print(double_first(numbers));
    print(double_first(empty));
    print(double_first(strings));
}
```



## 4.4 使用 `?`

在上个示例中，调用 parse 后总是立即将错误从标准库的错误 map 到装箱错误，但 and_then 不够灵活：

```rust
.and_then(|s| s.parse::<i32>()
	.map_err(|e| e.into()))
```

`?` 的解释：

- unwrap
- `return Err(From::from(err))`

由于 `From::from` 是不同类型之间的转换工具，也就是说，如果在错误可转换成返回类型地方使用 `?`，它将自动转换成返回类型

```rust
use std::{error, fmt};

type Result<T> = std::result::Result<T, Box<dyn error::Error>>;

#[derive(Debug, Clone)]
struct EmptyVec;

impl fmt::Display for EmptyVec {
    fn fmt(&self, f: &mut fmt::Formatter<'_>) -> fmt::Result {
        write!(f, "invalid first item to double")
    }
}

impl error::Error for EmptyVec {

}

fn double_first(vec: Vec<&str>) -> Result<i32> {
    // 使用 `?` 立即得到内部值
    let first = vec.first().ok_or(EmptyVec)?;
    let parsed = first.parse::<i32>()?;
    Ok(parsed * 2)
}
fn print(result: Result<i32>) {
    match result {
        Ok(n) => println!("The first double is {}", n),
        Err(e) => println!("Error: {}", e),
    }
}

fn main() {
    let numbers = vec!["21", "42", "16"];
    let empty = vec![];
    let strings = vec!["do", "13", "20"];

    print(double_first(numbers));
    print(double_first(empty));
    print(double_first(strings));
}
```



## 4.5 包裹错误

将错误装箱改成把它包裹到自定义的错误类型中

```rust
use std::{error, fmt};
use std::num::ParseIntError;

type Result<T> = std::result::Result<T, DoubleError>;

#[derive(Debug, Clone)]
enum DoubleError {
    EmptyVec,
    Parse(ParseIntError),
}

impl fmt::Display for DoubleError {
    fn fmt(&self, f: &mut fmt::Formatter<'_>) -> fmt::Result {
        match *self {
            DoubleError::EmptyVec => {
                write!(f, "invalid first item to double")
            },
            DoubleError::Parse(ref e) => e.fmt(f),
        }
    }
}

impl error::Error for DoubleError {
    fn source(&self) -> Option<&(dyn error::Error + 'static)> {
        match *self {
            DoubleError::EmptyVec => None,
            DoubleError::Parse(ref e) => Some(e),
        }
    }
}

impl From<ParseIntError> for DoubleError {
    fn from(e: ParseIntError) -> Self {
        DoubleError::Parse(e)
    }
}

fn double_first(vec: Vec<&str>) -> Result<i32> {
    let first = vec.first().ok_or(DoubleError::EmptyVec)?;
    let parsed = first.parse::<i32>()?;
    Ok(parsed * 2)
}

fn print(result: Result<i32>) {
    match result {
        Ok(n) => println!("The first double is {}", n),
        Err(e) => println!("Error: {}", e),
    }
}

fn main() {
    let numbers = vec!["21", "42", "16"];
    let empty = vec![];
    let strings = vec!["do", "13", "20"];

    print(double_first(numbers));
    print(double_first(empty));
    print(double_first(strings));
}
```



# 5. 遍历 Result

`Item::map` 操作可能失败：

```rust
fn main() {
    let strings = vec!["do", "12", "37"];
    let numbers: Vec<_> = strings
        .into_iter()
        .map(|s| s.parse::<i32>())
        .collect();

    println!("Results: {:?}", numbers);
}
```



## 5.1 `filter_map` 忽略失败项

`filter_map` 会调用一个函数，过滤掉为 `None` 的所有结果

```rust
fn main() {
    let strings = vec!["do", "12", "37"];
    let numbers: Vec<_> = strings
        .into_iter()
        .filter_map(|s| s.parse::<i32>().ok())
        .collect();

    println!("Result: {:?}", numbers);
}
```



## 5.2 `collect()` 使整个操作失败

`Result` 实现了 `FromIter`，因此结果的向量（`Vec<Result<T, E>>`）可以被转换成结果包裹着向量（`Result<Vec<T>, E>`）。一旦找到一个 `Result::Err` ，遍历就被终止

```rust
fn main() {
    let strings = vec!["do", "12", "37"];
    let numbers: Result<Vec<_>, _>= strings
        .into_iter()
        .map(|s| s.parse::<i32>())
        .collect();

    println!("Result: {:?}", numbers);
}
```



## 5.3 `partition()` 收集所有合法的值与错误

```rust
fn main() {
    let strings = vec!["do", "12", "37"];
    let (numbers, errors): (Vec<_>, Vec<_>) = strings
        .into_iter()
        .map(|s| s.parse::<i32>())
        .partition(Result::is_ok);

    println!("numbers: {:?}, errors: {:?}", &numbers, errors);

    let numbers: Vec<_> = numbers.into_iter().map(Result::unwrap).collect();
    println!("numbers: {:?}", numbers);

    let errors: Vec<_> = errors.into_iter().map(Result::unwrap_err).collect();
    println!("errors: {:?}", errors);
}
```



# 6. 错误处理方法

## 6.1 unwrap

提取 Option 或 Result 类型中的值



### 6.1.1 unwrap

如果值是 Some 或 Ok，它将返回值，如果值是 None 或 Err，将导致程序崩溃。不安全

```rust
let mut x: i32 = 5;
x.try_into().unwrap();
```



### 6.1.2 unwrap_or

值是 None 或 Err 时，提供一个默认值

```rust
let mut x: i32 = 5;
x.try_into().unwrap_or(0);
```



### 6.1.3 unwrap_or_else

值是 None 或 Err 时，提供一个函数，处理返回值

```rust
let mut x: i32 = 5;
x.try_into().unwrap_or_else(|e| panic!("Couldn't convert the i32, error {}", e));
```



## 6.2 ?

只有在返回 Result 或 Option 的函数中才能使用

```rust
fn setup<'a>(
	ttf_context: &'a Sd12TtfContext,
    canvas: sd12::render::Canvas<sd12::video::Window>,
    event_pump: sd12::EventPump,
    texture_creator: &'a sd12::render::TextureCreator<sd12::video::WindowContext>,
) -> Result<crate::Game::Game<'a>, String> {
    let current_path = std::env::current_dir().map_err(|e| e.to_string())?;
    ...
}
```



## 6.3 expect

错误时依旧崩溃，但会输出一条错误消息

```rust
let mut x: i32 = 5;
x.try_into().expect("Couldn't convert to a u32");
```



## 6.4 模式匹配

最佳处理方法之一，在模式匹配时，可以对错误做任何事情，比如回退到默认值等



### 6.4.1 match

```rust
let current_path = match std::env::current_dir() {
    Ok(current_path) => current_path.join("assets"),
    Err(_e) => std::path::Path::new("assets").to_path_buf(),
}
```



### 6.4.2 if let

```rust
let val: Option<i32> = Some(10);
if let Some(v) = val {
    println!("Value: {}", v);
} else {
    println!("No value");
}
```



### 6.4.3 while let

```rust
let mut numbers = vec![Some(1), Some(2), None, Some(4), Some(5)];
while let Some(Some(number)) = numbers.pop() {
    println!("Processing number: {}", number);
} 
```































































