# 1. 错误处理

## 1.1 panic

最简单的错误处理机制就是 panic，它会打印一个错误消息，然后回退(unwind)任务，退出程序

```rust
fn give_princess(gift: &str) {
    if gift == "snake" {
        panic!("god damn!!!");
    }

    println!("I love {}s!!!", gift);
}

fn main() {
    give_princess("teddy bear");
    give_princess("snake");
    give_princess("babbie");
}
```

默认情况下，当发生 `panic` 时，程序开始 *unwind*，这意味着 Rust 会回溯堆栈并清理它遇到的每个函数的数据。但是，回溯和清理工作非常繁重。因此，Rust 允许你选择立即中止的替代方案，这将结束程序而不进行清理。

如果在项目中需要使生成的二进制文件尽可能小，可以通过在 `Cargo.toml` 文件中添加相应的配置，来从展开切换到在发生恐慌时中止。

```toml
[profile.release]
panic = 'abort'
```



开启 `RUST_BACKTRACE=1`，跟踪错误栈：

```bash
$ RUST_BACKTRACE=1 cargo run 

$ RUST_BACKTRACE=1 cargo run --release
```



## 1.2 Option

枚举类型 `Option<T>`:

- `Some(T)`：找到一个属于 T 类型的元素
- `None`：找不到相应元素

处理方式：

- match 显式处理
- unwrap 隐式处理，它要么返回 Some 内部的元素，要么就 panic



## 1.3 Result

Result 是 Option 类型的扩展，它可以有两个结果的其中一个：

- `Ok<T>`：找到 T 元素
- `Err<E>`：找到 E 元素，E 即错误类型

```rust
enum Result<T, E> {
    Ok(T),
    Err(E),
}
```



### 1.3.1 别名

```rust
use std::num::ParseIntError;

type AliasedResult<T> = Result<T, ParseIntError>;

fn multiply(s1: &str, s2: &str) -> AliasedResult<i32> {
    s1.parse::<i32>().and_then(|n1| {
        s2.parse::<i32>().map(|n2| n1 * n2)
    })
}

fn print(result: AliasedResult<i32>) {
    match result {
        Ok(n) => println!("n is {}", n),
        Err(e) => println!("Error: {}", e),
    }
}

fn main() {
    let r1 = multiply("5", "7");
    print(r1);

    let r2 = multiply("t", "2");
    print(r2);
}
```



### 1.3.2 匹配不同的错误

```rust
use std::fs::File;
use std::io::ErrorKind;

fn main() {
    let greeting_file_result = File::open("hello.txt");

    match greeting_file_result {
        Ok(file) => file,
        Err(error) => match error.kind() {
            ErrorKind::NotFound => match File::create("hello.txt") {
                Ok(fc) => fc,
                Err(e) => panic!("Prombles creating the file: {e:?}"),
            },
            other_error => {
                panic!("Probles opening the file: {other_error:?}");
            },
        },
    };
}
```

替代方法：

```rust
fn main() {
    let greeting_file = File::open("hello.txt").unwrap_or_else(|error| {
        if  error.kind() == ErrorKind::NotFound {
            File::create("hello.txt").unwrap_or_else(|error| {
                panic!("Problem creating the file: {error:?}");
            })
        } else {
            panic!("Problem opening the file: {error:?}")
        }
    });
}
```



### 1.3.3 提前返回

如果发生错误，则停止函数指向并返回错误，这样的代码更好写、更易读。

```rust
use std::num::ParseIntError;

fn multiply(s1: &str, s2: &str) -> Result<i32, ParseIntError> {
    let n1 = match s1.parse::<i32>() {
        Ok(n1) => n1,
        Err(e) => return Err(e),
    };

    let n2 = match s2.parse::<i32>() {
        Ok(n2) => n2,
        Err(e) => return Err(e),
    };

    Ok(n1 * n2)
}

fn print(result: Result<i32, ParseIntError>) {
    match result {
        Ok(n) => println!("n is {}", n),
        Err(e) => println!("Error: {}", e),
    }
}

fn main() {
    let r1 = multiply("3", "4");
    print(r1);

    let r2 = multiply("w", "8");
    print(r2);
}
```



### 1.3.4 `try!` 宏

`try!` 宏具有和 `?` 相同的功能，主要使用在老代码中

```rust
use std::num::ParseIntError;

fn multiply(s1: &str, s2: &str) -> Result<i32, ParseIntError> {
    // `try!()` macro is deprecated
    let n1 = r#try!(s1.parse::<i32>());
    let n2 = r#try!(s2.parse::<i32>());

    Ok(n1 * n2)
}

fn print(result: Result<i32, ParseIntError>) {
    match result {
        Ok(n) => println!("n is {}", n),
        Err(e) => println!("Error: {}", e),
    }
}

fn main() {
    print(multiply("5", "8"));
    print(multiply("s", "4"));
}
```



## 1.4 `?` 操作符

### 1.4.1 Option

`?` 简化 match 匹配的复杂性

```rust
struct Person {
    job: Option<Job>
}

#[derive(Copy, Clone)]
struct Job {
    phone_number: Option<PhoneNumber>
}

#[derive(Copy, Clone)]
struct PhoneNumber {
    area_code: Option<u8>,
    number: u32,
}

impl Person {
    fn work_phone_area_code(&self) -> Option<u8> {
        // 没有`?`运算符的话，将需要很多的嵌套的 `match` 语句
        self.job?.phone_number?.area_code
    }
}

fn main() {
    let p = Person {
        job: Some(Job{
            phone_number: Some(PhoneNumber{
                area_code: Some(25),
                number: 56712111,
            })
        })
    };

    assert_eq!(p.work_phone_area_code(), Some(25));
}
```



### 1.4.2 Result

unwrap 可能导致 panic，需要层层嵌套判断。如果只想把里面的变量拿出来，可使用 `?`，它几乎就等于一个返回 Error 而不是 panic 的 unwrap

```rust
use std::num::ParseIntError;

fn multiply(s1: &str, s2: &str) -> Result<i32, ParseIntError> {
    let n1 = s1.parse::<i32>()?;
    let n2 = s2.parse::<i32>()?;

    Ok(n1 * n2)
}

fn print(result: Result<i32, ParseIntError>) {
    match result {
        Ok(n) => println!("n is {}", n),
        Err(e) => println!("Error: {}", e),
    }
}

fn main() {
    let r1 = multiply("3", "9");
    print(r1);

    let r2 = multiply("t", "3");
    print(r2);
}
```



## 1.5 其它方法

### 1.5.1 unwrap

提取 Option 或 Result 类型中的值



**unwrap**：如果值是 Some 或 Ok，它将返回值，如果值是 None 或 Err，将导致程序崩溃。不安全

```rust
let mut x: i32 = 5;
x.try_into().unwrap();
```



**unwrap_or**：值是 None 或 Err 时，提供一个默认值

```rust
let mut x: i32 = 5;
x.try_into().unwrap_or(0);
```



**unwrap_or_else**：值是 None 或 Err 时，提供一个函数，处理返回值

```rust
let mut x: i32 = 5;
x.try_into().unwrap_or_else(|e| panic!("Couldn't convert the i32, error {}", e));
```



### 1.5.2 expect

错误时依旧崩溃，但会输出一条错误消息

```rust
let mut x: i32 = 5;
x.try_into().expect("Couldn't convert to a u32");
```





# 2. 组合器

**组合器设计模式**：将对象组合成树形结构，以表示“部分整体”的层次结构。组合模式使得用户对单个对象和组合对象的使用具有一致性。



## 2.1 `or()` 和 `and()`

对两个表达式做逻辑组合，最终返回 `Option` 或 `Result`

- `or()` ，表达式按顺序求职，若任何一个表达式的结果是 `Some` 或 `Ok`，则该值会立即返回
- `and()`，若两个表达式的结果都是 `Some` 或 `Ok`，则**第二个表达式中的值被返回。若任何一个的结果是 `None` 或 `Err`，则立即返回

```rust
fn main() {
    let s1 = Some(1);
    let s2 = Some(2);
    let n = None;
    
    assert_eq!(s1.or(s2), s1);
    assert_eq!(s1.or(n), s1);
    assert_eq!(s1.and(s2), s2); // 注意返回第二个表达式
    assert_eq!(s1.and(n), n);
    
    // xor 只能用于 Option
    assert_eq!(s1.xor(s2), n);
}
```



## 2.2 `or_else()` 和 `and_then()`

与 `or()` 和 `and()` 类似，但第二个表达式是一个闭包

```rust
fn main() {
    let r1: Result<&str, &str> = Ok("success");
    let r2: Result<&str, &str> = Err("failure");

    assert_eq!(r1.or_else(|_| Ok("1")), r1);
    assert_eq!(r1.and_then(|_| Ok("1")), Ok("1"));
    
    assert_eq!(r2.or_else(|_| Ok::<&str, &str>("2")), Ok("2"));
    assert_eq!(r2.and_then(|_| Ok("2")), r2);
}
```



## 2.3 `filter`

用于对 `Option` 进行过滤：

```rust
fn main() {
    let s1 = Some(8);
    let s2 = Some(5);
    let n = None;
    
    let is_even = |n: &i32| n % 2 == 0;
    
    assert_eq!(s1.filter(is_even), s1);
    assert_eq!(s2.filter(is_even), n);
    assert_eq!(n.filter(is_even), n);
}
```



## 2.4 `map` 和 `map_err()`

将 `Some` 或 `Ok` 中的值映射为另一个：

```rust
fn main() {
    let char_count = |s: &str| s.chars().count();

    let s1 = Some("abcde");
    let s2 = Some(5);
    assert_eq!(s1.map(char_count), s2);
    
    let n1 = None;
    let n2 = None;
    assert_eq!(n1.map(char_count), n2);
    
    let o1: Result<&str, &str> = Ok("abcde");
    let o2: Result<usize, &str> = Ok(5);
    assert_eq!(o1.map(char_count), o2);
    
    // 无法修改Err的值
    let e1: Result<&str, &str> = Err("abcde");
    let e2: Result<usize, &str> = Err("abcde");
    assert_eq!(e1.map(char_count), e2);
    
    // 修改Err的值
    let e3: Result<&str, &str> = Err("abcde");
    let e4: Result<&str, usize> = Err(5);
    assert_eq!(e3.map_err(char_count), e4);
}
```



## 2.5 `map_or()` 和 `map_or_else()`

`map_or()` 在 `map()` 的基础上提供一个默认值：

```rust
fn main() {
    const DEFAULT: u32 = 1;
    let fn_closure = |n: u32| n + 2;
    
    let r: Result<u32, ()> = Ok(5);
    assert_eq!(r.map_or(DEFAULT, fn_closure), 7);

    let n: Option<u32> = None;
    assert_eq!(n.map_or(DEFAULT, fn_closure), DEFAULT);
}
```



`map_or_else()` 通过一个闭包来提供默认值：

```rust
fn main() {
    let fn_closure = |n: u32| n + 2;
    let fn_default = || 1; // 匿名函数不能携带参数
    
    let s = Some(5);
    let n: Option<u32> = None;
    assert_eq!(s.map_or_else(fn_default, fn_closure), 7);
    assert_eq!(n.map_or_else(fn_default, fn_closure), 1);
    
    let o = Ok(10);
    let e = Err(6);
    let fn_default_for_result = |n: u32| n - 1;
    
    assert_eq!(o.map_or_else(fn_default_for_result, fn_closure), 12);
    assert_eq!(e.map_or_else(fn_default_for_result, fn_closure), 5);
}
```



## 2.6 `ok_or()` 和 `ok_or_else()`

支持将 `Option` 转换为 `Result`

 `ok_or` 接收一个默认的 `Err` 参数：

 ```rust
fn main() {
    const ERR_MSG: &str = "error message";
    
    let s = Some("abcde");
    let n: Option<&str> = None;
    
    let o = Ok("abcde");
    let e = Err(ERR_MSG);
    
    assert_eq!(s.ok_or(ERR_MSG), o);
    assert_eq!(n.ok_or(ERR_MSG), e);
}
 ```



`ok_or_else` 接收一个闭包作为 `Err` 参数：

```rust
fn main() {
    let fn_err_msg = || "error message";
    
    let s = Some("abcde");
    let n: Option<&str> = None;
    
    let o = Ok("abcde");
    let e = Err(fn_err_msg());
    
    assert_eq!(s.ok_or_else(fn_err_msg), o);
    assert_eq!(n.ok_or_else(fn_err_msg), e);
}
```



## 2.7 示例：简化 match

Option 的 map, and_then 等组合算子也为 Result 实现了

```rust
#![allow(dead_code)]
use std::num::ParseIntError;

fn multiply_v1(s1: &str, s2: &str) -> Result<i32, ParseIntError> {
    match s1.parse::<i32>() {
        Ok(n1) => {
            match s2.parse::<i32>() {
                Ok(n2) => {
                    Ok(n1 * n2)
                },
                Err(e) => Err(e),
            }
        },
        Err(e) => Err(e),
    }
}

fn multiply_v2(s1: &str, s2: &str) -> Result<i32, ParseIntError> {
    s1.parse::<i32>().and_then(|n1| {
        s2.parse::<i32>().map(|n2| n1 * n2)
    })
}

fn print(result: Result<i32, ParseIntError>) {
    match result {
        Ok(n) => println!("n is {}", n),
        Err(e) => println!("Error: {}", e),
    }
}

fn main() {
    let r1 = multiply_v2("32", "5");
    print(r1);

    let r2 = multiply_v2("12", "hk");
    print(r2);
}
```



# 3. 处理多种错误

## 3.1 从 Option 中取出 Result

处理混合错误类型的最基本手段就是让它们相互包容

```rust
use std::num::ParseIntError;

// 通过 Option 包装 Result
fn double_first_v1(vec: Vec<&str>) -> Option<Result<i32, ParseIntError>> {
    vec.first().map(|first| {
        first.parse::<i32>().map(|n| n * 2)
    })
}

// Option 和 Result 互换
fn double_first(vec: Vec<&str>) -> Result<Option<i32>, ParseIntError> {
    let opt = vec.first().map(|first| {
       first.parse::<i32>().map(|n| n * 2)
    });

    opt.map_or(Ok(None), |r| r.map(Some))
}

fn main() {
    let numbers = vec!["21", "42", "16"];
    let empty = vec![];
    let strings = vec!["do", "13", "20"];

    println!("The first double is {:?}", double_first(numbers));
    println!("The first double is {:?}", double_first(empty));
    println!("The first double is {:?}", double_first(strings));
}
```



## 3.2 自定义错误类型

自定义错误类型：

- 用同一个类型代表多种错误
- 向用户提供清楚的错误信息
- 能够容易地与其他类型比较
  - 好的例子：Err(EmptyVec)
  - 坏的例子：Err("Please use a vector with at least one element".to_owned())
- 能够容纳错误的具体信息
  - 好的例子：Err(BadChar(c, position))
  - 坏的例子：Err("+ cannot be used here".to_owned())
- 能够与其他错误很好地整合



标准库可复用的 `std::error::Error` 特征：

```rust
use std::fmt::{Debug, Display};

pub trait Error: Debug + Display {
    fn source(&self) -> Option<&(Error + 'static)> { .. }
}
```

自定义错误类型只需要实现 `Debug` 和 `Display` 特征即可，`source` 方法可选，而 `Debug` 特征往往也无需手动实现，可以直接通过 derive 来派生。



### 3.2.1 最简单的错误

```rust
use std::fmt::{self, Debug, Display};

// 自动派生Debug特征
#[derive(Debug)]
struct AppError;

impl Display for AppError {
    fn fmt(&self, f: &mut fmt::Formatter) -> fmt::Result {
        write!(f, "An error occurred, please try again.")
    } 
}

fn produce_error() -> Result<(), AppError> {
    Err(AppError)
}

fn main() {
    match produce_error() {
        Err(e) => eprintln!("{}", e),
        _ => println!("No error"),
    }
    
    eprintln!("{:?}", produce_error());
}
```

实现 Debug 和 Display特征并不是作为 `Err` 使用的必要条件，但实现它们有如下优势：

- 打印错误，需要实现这两个特征
- 可以将自定义错误转换为 `Box<dyn std::error::Error>` 特征对象，**归一化不同错误类型**



### 3.2.2 更详尽得错误

在错误中定义错误码和错误信息：

```rust
use std::fmt::{self, Debug, Display};

struct AppError {
    code: usize,
    message: String,
}

impl Display for AppError {
    fn fmt(&self, f: &mut fmt::Formatter) -> fmt::Result {
        let err_msg = match self.code {
            404 => "Sorry, cann't find the page.",
            _ => "Sorry, something wrong, please try again.",
        };
    
        write!(f, "{}", err_msg)
    } 
}

impl Debug for AppError {
    fn fmt (&self, f: &mut fmt::Formatter) -> fmt::Result {
        write!(f, "AppError {{ code: {}, message: {} }}", self.code, self.message)
    }
}

fn produce_error() -> Result<(), AppError> {
    Err(AppError {
        code: 404,
        message: "Page not found".to_string(),
    })
}

fn main() {
    match produce_error() {
        Err(e) => eprintln!("{}", e),
        _ => println!("No error"),
    }
    
    eprintln!("{:#?}", produce_error());
}
```



### 3.2.3 错误转换 `From` 特征

标准库 `std::convert::From` 特征：

```rust
pub trait From<T>: Sized {
    fn from(_: T) -> Self;
}
```



自定义错误实现 `From` 特征：

```rust
use std::fs::File;
use std::io;

#[derive(Debug)]
struct AppError {
    kind: String,
    message: String,
}

impl From<io::Error> for AppError {
    fn from(error: io::Error) -> Self {
        AppError {
            kind: String::from("io"),
            message: error.to_string(),
        }
    }
}

fn main() -> Result<(), AppError> {
    let _file = File::open("abc.txt")?; // "?"隐式强制转换，std::io::Error => AppError
    
    Ok(())
}
```



多个不同得错误转换成 `AppError` ：

```rust
use std::fs::File;
use std::io::{self, Read};
use std::num;

#[derive(Debug)]
struct AppError {
    kind: String,
    message: String,
}

impl From<io::Error> for AppError {
    fn from(error: io::Error) -> Self {
        AppError {
            kind: String::from("io"),
            message: error.to_string(),
        }
    }
}

impl From<num::ParseIntError> for AppError {
    fn from(error: num::ParseIntError) -> Self {
        AppError {
            kind: String::from("parse"),
            message: error.to_string(),
        }
    }
}

fn main() -> Result<(), AppError> {
    let mut file = File::open("abc.txt")?;
    
    let mut content = String::new();
    file.read_to_string(&mut content)?;
    
    let _number: usize;
    _number = content.parse()?;
    
    Ok(())
}
```



## 3.3 把错误装箱

如果想写简单的代码，又想保留原始错误信息，可将它们装箱 (Box)。但这样做的坏处是，被包装的错误类型，只能在运行时了解，而不能被静态地判别。

对任何实现了 Error trait 的类型，标准库 Box 通过 From 为其提供到 `Box<Error>` 的转换

```rust
use std::{error, fmt};

type Result<T> = std::result::Result<T, Box<dyn error::Error>>;

#[derive(Debug, Clone)]
struct EmptyVec;

impl fmt::Display for EmptyVec {
    fn fmt(&self, f: &mut fmt::Formatter<'_>) -> fmt::Result {
        write!(f, "invalid first item to double")
    }
}

impl error::Error for EmptyVec {
    fn description(&self) -> &str {
        "invalid first item to double"
    }

    fn cause(&self) -> Option<&dyn error::Error> {
        None
    }
}

fn double_first(vec: Vec<&str>) -> Result<i32> {
    vec.first()
        .ok_or_else(|| EmptyVec.into())  // 装箱
        .and_then(|s| {
            s.parse::<i32>()
                .map_err(|e| e.into()) // 装箱
                .map(|n| n * 2)
        })
}

fn print(result: Result<i32>) {
    match result {
        Ok(n) => println!("The first double is {}", n),
        Err(e) => println!("Error: {}", e),
    }
}

fn main() {
    let numbers = vec!["21", "42", "16"];
    let empty = vec![];
    let strings = vec!["do", "13", "20"];

    print(double_first(numbers));
    print(double_first(empty));
    print(double_first(strings));
}
```



## 3.4 使用 `?`

在上个示例中，调用 parse 后总是立即将错误从标准库的错误 map 到装箱错误，但 and_then 不够灵活：

```rust
.and_then(|s| s.parse::<i32>()
	.map_err(|e| e.into()))
```

`?` 的解释：

- unwrap
- `return Err(From::from(err))`

由于 `From::from` 是不同类型之间的转换工具，也就是说，如果在错误可转换成返回类型地方使用 `?`，它将自动转换成返回类型

```rust
use std::{error, fmt};

type Result<T> = std::result::Result<T, Box<dyn error::Error>>;

#[derive(Debug, Clone)]
struct EmptyVec;

impl fmt::Display for EmptyVec {
    fn fmt(&self, f: &mut fmt::Formatter<'_>) -> fmt::Result {
        write!(f, "invalid first item to double")
    }
}

impl error::Error for EmptyVec {

}

fn double_first(vec: Vec<&str>) -> Result<i32> {
    // 使用 `?` 立即得到内部值
    let first = vec.first().ok_or(EmptyVec)?;
    let parsed = first.parse::<i32>()?;
    Ok(parsed * 2)
}
fn print(result: Result<i32>) {
    match result {
        Ok(n) => println!("The first double is {}", n),
        Err(e) => println!("Error: {}", e),
    }
}

fn main() {
    let numbers = vec!["21", "42", "16"];
    let empty = vec![];
    let strings = vec!["do", "13", "20"];

    print(double_first(numbers));
    print(double_first(empty));
    print(double_first(strings));
}
```



## 3.5 包裹错误

将错误装箱改成把它包裹到自定义的错误类型中

```rust
use std::{error, fmt};
use std::num::ParseIntError;

type Result<T> = std::result::Result<T, DoubleError>;

#[derive(Debug, Clone)]
enum DoubleError {
    EmptyVec,
    Parse(ParseIntError),
}

impl fmt::Display for DoubleError {
    fn fmt(&self, f: &mut fmt::Formatter<'_>) -> fmt::Result {
        match *self {
            DoubleError::EmptyVec => {
                write!(f, "invalid first item to double")
            },
            DoubleError::Parse(ref e) => e.fmt(f),
        }
    }
}

impl error::Error for DoubleError {
    fn source(&self) -> Option<&(dyn error::Error + 'static)> {
        match *self {
            DoubleError::EmptyVec => None,
            DoubleError::Parse(ref e) => Some(e),
        }
    }
}

impl From<ParseIntError> for DoubleError {
    fn from(e: ParseIntError) -> Self {
        DoubleError::Parse(e)
    }
}

fn double_first(vec: Vec<&str>) -> Result<i32> {
    let first = vec.first().ok_or(DoubleError::EmptyVec)?;
    let parsed = first.parse::<i32>()?;
    Ok(parsed * 2)
}

fn print(result: Result<i32>) {
    match result {
        Ok(n) => println!("The first double is {}", n),
        Err(e) => println!("Error: {}", e),
    }
}

fn main() {
    let numbers = vec!["21", "42", "16"];
    let empty = vec![];
    let strings = vec!["do", "13", "20"];

    print(double_first(numbers));
    print(double_first(empty));
    print(double_first(strings));
}
```



# 4. 遍历 Result

`Item::map` 操作可能失败：

```rust
fn main() {
    let strings = vec!["do", "12", "37"];
    let numbers: Vec<_> = strings
        .into_iter()
        .map(|s| s.parse::<i32>())
        .collect();

    println!("Results: {:?}", numbers);
}
```



## 4.1 `filter_map` 忽略失败项

`filter_map` 会调用一个函数，过滤掉为 `None` 的所有结果

```rust
fn main() {
    let strings = vec!["do", "12", "37"];
    let numbers: Vec<_> = strings
        .into_iter()
        .filter_map(|s| s.parse::<i32>().ok())
        .collect();

    println!("Result: {:?}", numbers);
}
```



## 4.2 `collect()` 使整个操作失败

`Result` 实现了 `FromIter`，因此结果的向量（`Vec<Result<T, E>>`）可以被转换成结果包裹着向量（`Result<Vec<T>, E>`）。一旦找到一个 `Result::Err` ，遍历就被终止

```rust
fn main() {
    let strings = vec!["do", "12", "37"];
    let numbers: Result<Vec<_>, _>= strings
        .into_iter()
        .map(|s| s.parse::<i32>())
        .collect();

    println!("Result: {:?}", numbers);
}
```



## 4.3 `partition()` 收集所有合法的值与错误

```rust
fn main() {
    let strings = vec!["do", "12", "37"];
    let (numbers, errors): (Vec<_>, Vec<_>) = strings
        .into_iter()
        .map(|s| s.parse::<i32>())
        .partition(Result::is_ok);

    println!("numbers: {:?}, errors: {:?}", &numbers, errors);

    let numbers: Vec<_> = numbers.into_iter().map(Result::unwrap).collect();
    println!("numbers: {:?}", numbers);

    let errors: Vec<_> = errors.into_iter().map(Result::unwrap_err).collect();
    println!("errors: {:?}", errors);
}
```



# 5. 归一化不同错误类型

归一化错误得三种方式：

- 使用特征对象 `Box<dyn Error>`
- 自定义错误类型
- 使用 `thiserror`



## 5.1 `Box<dyn Error>`

自定义错误实现 `Debug + Display` 特征得主要原因就是为了转换成 `Error` 特征对象，而特征对象恰恰是在同一个地方使用不同类型得关键：

```rust
use std::error::Error;

fn render() -> Result<String, Box<dyn Error>> {
    let file = std::env::var("MARKDOWN")?;
    let source = std::fs::read_to_string(file)?;
    Ok(source)
}

fn main() {
    match render() {
        Err(e) => eprintln!("An error occurred: {}", e),
        _ => println!("No error"),
    }
}
```

存在的问题：`Result` 实际上不会限制错误的类型，即一个类型就算不实现 `Error` 特征，它依然可以在 `Result<T, E>` 中作为 `E` 来使用，此时这种特征对象的解决方案是无能无力的。



## 5.2 自定义错误类型

与特征对象相比，自定义错误类型虽然麻烦，但它非常灵活，不会有上面的类似限制：

```rust
fn render() -> Result<String, MyError> {
    let file = std::env::var("MARKDOWN")?;
    let source = std::fs::read_to_string(file)?;
    Ok(source)
}

fn main() {
    match render() {
        Err(e) => eprintln!("An error occurred: {}", e),
        _ => println!("No error"),
    }
}

#[derive(Debug)]
enum MyError {
    EnvironmentVariableNotFound,
    IOError(std::io::Error),
}

impl From<std::env::VarError> for MyError {
    fn from(_: std::env::VarError) -> Self {
        Self::EnvironmentVariableNotFound
    }
}

impl From<std::io::Error> for MyError {
    fn from(err: std::io::Error) -> Self {
        Self::IOError(err)
    }
}

impl std::error::Error for MyError {}

impl std::fmt::Display for MyError {
    fn fmt(&self, f: &mut std::fmt::Formatter<'_>) -> std::fmt::Result {
        match self {
            MyError::EnvironmentVariableNotFound => write!(f, "Environment variable not found"),
            MyError::IOError(err) => write!(f, "IO Error: {}", err.to_string()),
        }
    }
}
```



## 5.3 `thiserror`

通过注释，简化错误处理

```rust
fn render() -> Result<String, MyError> {
    let file = std::env::var("MARKDOWN")?;
    let source = std::fs::read_to_string(file)?;
    Ok(source)
}

fn main() {
    match render() {
        Err(e) => eprintln!("An error occurred: {}", e),
        _ => println!("No error"),
    }
}

#[derive(Debug, thiserror::Error)]
enum MyError {
    #[error("Enviroment variable not found")]
    EnvironmentVariableNotFound(#[from] std::env::VarError),
    
    #[error(transparent)]
    IOError(#[from] std::io::Error),
}
```



























